Workbook
Name 纪念物: 纪念物表!$B$2:$B$37
Name 军官: 辅助表!$B$25:$D$25
Name 猎人: 辅助表!$B$23:$D$23
Name 流浪者: 辅助表!$B$29:$D$29
Name 牧师: 辅助表!$B$26:$D$26
Name 仆人: 辅助表!$B$28:$D$28
Name 神秘学家: 辅助表!$B$24:$D$24
Name 私家侦探: 辅助表!$B$27:$D$27
Name 通用天赋: 天赋表!$B$35:$B$58
Name 吸血鬼猎人: 辅助表!$B$31:$D$31
Name 学者: 辅助表!$B$21:$D$21
Name 医生: 辅助表!$B$22:$D$22
Name 作家: 辅助表!$B$30:$D$30

Sheet 角色卡
A1: 姓名 | I1: 动机 | U1: 纪念物 | AE1: 人物背景
A3: 玩家
I4: 创伤
U5: 优势
I7: 黑暗秘密
U9: 状态
I10: 关系 | U10: 物理 | V10: 力竭 | Y10: ○ | Z10: 精神 | AA10: 愤怒 | AD10: ○
I11: PC1 | V11: 伤痕累累 | Y11: ○ | AA11: 恐惧 | AD11: ○
V12: 创伤 | Y12: ○ | AA12: 绝望 | AD12: ○
I13: PC2 | V13: 崩溃 | Y13: ○ | AA13: 崩溃 | AD13: ○
U14: 洞察＆缺陷
A15: 泛型 | I15: PC3
A16: 年龄 | F16: =IF(D16>=51,"老年(51+)",IF(D16>=26,"中年(26-50)",IF(D16>=17,"青年(17-25)","年龄错误"))) -> 年龄错误
A17: 资源 | C17: =IFERROR(VLOOKUP(E18,资产表!A2:B9,2,FALSE),"") | F17: 资产 | I17: PC4
A18: =IFERROR(VLOOKUP(D15,辅助表!A2:B12,2,FALSE),"") | B18: + | D18: = | E18: =IFERROR(A18+C18,"") | U18: 经验 | W18: ○ | X18: ○ | Y18: ○ | Z18: ○ | AA18: ○ | AB18: ○ | AC18: ○ | AD18: ○ | AE18: 笔记
A19: 属性&技能 | M19: 属性点 | P19: =VLOOKUP(角色卡!F16,辅助表!A16:E18,4,FALSE) -> #N/A | Q19: 技能点 | T19: =VLOOKUP(角色卡!F16,辅助表!A16:E18,5,FALSE) -> #N/A | U19: 1、你参与了本次游戏吗？（角色总是至少能获得这一点经验）
A20: 体能 | F20: 精准 | K20: 逻辑 | P20: 共情
A21: 敏捷 | F21: 医学 | K21: 调查 | P21: 启迪 | U21: 2、你是否和Vaesen对峙过？
A22: 近身战斗 | F22: 远程战斗 | K22: 学习 | P22: 操控人心 | U22: 3、你是否辨别了一种以前不了解的Vaesen？
A23: 力量 | F23: 隐秘行动 | K23: 警觉 | P23: 观察
A24: 天赋 | E24: 说明 | U24: 4、你的黑暗秘密是否影响了你？
E25: =IFERROR(VLOOKUP(A25,天赋表!B2:C58,2,FALSE),"") | U25: 5、你是否为了保护他人而犯险？
E26: =IFERROR(VLOOKUP(A26,天赋表!B2:C58,2,FALSE),"") | U26: 6、你是否学会了什么（是什么呢）？
E27: =IFERROR(VLOOKUP(A27,天赋表!B2:C58,2,FALSE),"") | U27: 7、你是否开发了自己的大本营？
E28: =IFERROR(VLOOKUP(A28,天赋表!B2:C58,2,FALSE),"") | U28: 8、你是否做出了非凡的行动？
A29: 装备 | E29: 描述 | M29: 加成 | O29: 护甲 | AA29: 防护 | AC29: 敏捷
O31: 武器 | V31: 伤害 | X31: 范围 | Z31: 加成 | AB31: 技能
A36: =IFERROR(_xlfn.CONCAT("职业装备:",VLOOKUP(D15,辅助表!A2:I12,9,FALSE))," ")

Sheet 天赋表
A1: 职业 | B1: 天赋 | C1: 描述
A2: 学者 | B2: 书虫 | C2: 从书籍中或图书馆中寻找线索时，学习检定+2。
B3: 学富五车 | C3: 你可以学习检定来构建游戏中地点和现象的真相。你可以知道某个地点以玻璃工人而闻名，或是有犯罪分子在该地区活动。由GM可以判断什么合适，什么是你可以知道的。你不应创造和“自在之物”有关的内容。
B4: 知识是可靠的 | C4: 在学习检定中无视状态的影响。
A5: 医生 | B5: 军医 | C5: 在面对尸体或是残破的人体时，恐惧检定+2。
B6: 主任医师 | C6: 当使用医学检定治疗其他玩家时，你的成功可以治疗4个症状，而非3个。该天赋同样适用于额外成功。
B7: 应急医学 | C7: 医学检定时无视状态影响。
A8: 猎人 | B8: 寻血犬 | C8: 追踪猎物时警觉检定+2。
B9: 草药专家 | C9: 通过野外的草药，你可以在没有医疗用品的情况下使用医学检定。
B10: 神射手 | C10: 当你成功埋伏并首次攻击目标时，你的远程战斗检定+2。
A11: 神秘学家 | B11: 魔术手法 | C11: 当你使用魔术手法影响他人时，你可以用隐秘行动检定替代操控人心检定。
B12: 灵媒 | C12: 你可以通过观察检定来进行降灵仪式，并借此联络死者并预测他人的未来。额外的成功会提供更多信息，延长联系时间，或者让灵体直接现身。若检定失败，你会得到不准确的信息，遭受攻击，或承受某种状态。
B13: 恐惧来袭 | C13: 你可以使用1级的恐惧检定（见第68页）来实现恐惧打击。这是一个缓慢动作，且对“自在之物”无效。在你的区域里选择一个受害者，且目标NPC必须通过逻辑检定或共情检定。他可以获得和范围内友善单位个数相同的奖励骰。
A14: 军官 | B14: 久经沙场 | C14: 你对战斗司空见惯，进行先攻检定时，你可以抽取两张卡并任选一张。
B15: 绅士 | C15: 你被教育必须在社交场合控制好自己的行为和情绪，哪怕是在压力环境下也必须如此。在进行操控人心检定时，无视精神状态带来的惩罚
B16: 战术家 | C16: 当你在远程战斗检定中获得额外成功时，除了通常的可选效果外你还有一个额外选择，向一个友善单位下达指令。这必须消耗一个成功数。如果对方遵循你的指令，则可以在下一个检定中获得+2（可以多次给不同的人下达指令）。
A17: 牧师 | B17: 赦免 | C17: 玩家角色向你忏悔，袒露自己的行为时可以治愈三个状态，而非两个。
B18: 祝福 | C18: 每次游戏你可以祝福一个物品或另一个玩家。玩家角色或使用该物品的人将获得祝福优势，并在他们所选择的检定中+2。这一优势会在使用或谜题结束后失效。每个谜题你只能祝福一个角色或一件物品。
B19: 忏悔者 | C19: 在保密的谈话中，你可以使用观察检定替代操纵人心检定。
A20: 私家侦探 | B20: 鹰眼 | C20: 当你试图进行远程的观测时，你的警觉检定+2。
B21: 基础推演法 | C21: 每次游戏一次，你可以要求GM解释线索是如何串联的。
B22: 专注 | C22: 进行调查检定时无视状态带来的惩罚。
A23: 仆人 | B23: 忠诚 | C23: 当你发誓保护的人在场时，你的恐惧检定+2。
B24: 强硬如钉 | C24: 徒手战斗时，力量检定+2。
B25: 坚韧 | C25: 每次游戏一次，你可以在任何一次检定中无视状态带来的惩罚。
A26: 流浪者 | B26: 流浪者戏法 | C26: 当你试图在富人面前隐藏自己或某个物品时，隐秘行动检定+2。
B27: 疑心 | C27: 进行警觉检定时无视状态的影响。
B28: 云游 | C28: 每次谜题你都可以进行一个操控人心检定，以创造一个位于该地点的NPC，或是你曾经见过的人。GM决定在上次见面以来他的变化，以及他现在对你的看法。如果检定失败，他要么对你怀有敌意，要么就是他反过来非常需要你的帮助
A29: 作家 | B29: 自动书写 | C29: 你可以通过启迪检定引导灵体进行自动书写以获得线索。GM会提供或多或少的模糊线索，对未来的预测，或对敌人想法和经验的瞬间洞察。额外的成功会揭示更多的线索。如果检定失败，GM会决定你是否要承受某种状态，被附身，或是一种持续1D6小时的人格改变（具体由你决定是何种改变）。你可以在每次游戏中使用一次。
B30: 记者 | C30: 当你通过吸引或是哄骗他人以获得信息时，你可以使用启迪检定替代操控人心检定。
B31: 墨客 | C31: 进行启迪检定时无视状态的影响。
A32: 吸血鬼猎人 | B32: 吸血者恨意 | C32: 在面对各类吸血鬼及其子嗣（衍体）时的恐惧检定中获得+2。
B33: 穿刺者 | C33: 使用木桩进行近身战斗检定时获得+2。
B34: 猎杀时刻 | C34: 你得知一个自在之物的藏身地点时，恢复一个状态。
A35: - | B35: 战场经历 | C35: 治疗肉体重创时，医学检定+2。
A36: - | B36: 勇敢 | C36: 进行恐惧检定时，+1。
A37: - | B37: 近战训练 | C37: 进行格挡时，力量检定或近身战斗检定+2。
A38: - | B38: 联络人 | C38: 在每场游戏中，你可以确定自己已经认识了某个NPC，并且你们之间的关系是积极的。
A39: - | B39: 怯懦 | C39: 当你在战斗中受伤时，你可以通过一个隐秘行动检定来使其他玩家角色代替你承受伤害。这并不占用动作。如果检定失败，你必须承受1点额外伤害。每场战斗遭遇只能使用一次。
A40: - | B40: 骗术专精 | C40: 当进行谎言或者欺骗时，操控人心检定+2。
...

Sheet 资产表
A1: 值 | B1: 生活标准 | C1: 描述
A2: 1 | B2: 赤贫 | C2: 你完全依靠他人才能活下来。每天都要为了食物挣扎，属于你的东西很少，甚至没有。你可能会染上疾病，饥饿，或者靠毒品和酒精获得慰藉。
A3: 2 | B3: 贫穷 | C3: 你的生活十分简单。大部分时候桌上都有食物，虽然很少。如果你有孩子，他们不得不住在肮脏的环境里。你或许有几件换洗衣物和一点财产。失去收入来源对你和你的家庭将是灾难性的。
A4: 3 | B4: 挣扎 | C4: 你有一个朴素的家和固定的收入。你没有储蓄，但你能够为特殊场合给家人置办衣物，你的孩子能接受一定程度的教育——至少有几年。
A5: 4 | B5: 经济稳定 | C5: 你有自己的家，有一份提供稳定收入的工作。大部分和你一样的人存了一些钱。你偶尔会用甜食、旅行、漂亮的物件犒劳自己。紧急情况下有人愿意借你钱。
A6: 5 | B6: 中产 | C6: 你有一个家和自己的事业。你或许有一个或多个雇员，你知道如何为未来投资。你有储蓄，能借贷。你和你的家人生活得很好。
A7: 6 | B7: 殷实 | C7: 你有一个大房子或公寓。你可能有多种收入来源以及几个雇员。你不认为金钱是稀缺资源，而是用来增加资本和影响力的游戏。你的同伴都经济优渥，你几乎不和穷人有来往。你的家人可以去度假，你能负担起所有最新的发明创造。
A8: 7 | B8: 富有 | C8: 你继承了大笔钱财和房产。你或许拥有多处财产，雇佣了很多佣人，有许多收入来源。几乎没有你负担不起的东西。你和城里与国内的精英联系紧密，与高级官员、政客还有贵族关系良好。你唯一能看见穷人的机会是透过马车窗户。
A9: 8 | B9: 富得流油 | C9: 你是这个国家里最富有的人之一，与国家的统治者有直接联系。你拥有一处或多处城堡或庄园。任何开销对你来说都不算大。你能随意享用各种奢侈品，不用担心开销。

Sheet 纪念物表
A1: 序号 | B1: 纪念物
A2: 11 | B2: 风干的红玫瑰
A3: 12 | B3: 亲近之人的照片
A4: 13 | B4: 一枚有秘匣的印章戒指
A5: 14 | B5: 你父亲的手杖
A6: 15 | B6: 有秘密隔间的帽子
A7: 16 | B7: 一本以外语写成的书
A8: 21 | B8: 带刻字的扁酒壶
A9: 22 | B9: 一封旧情书
A10: 23 | B10: 一只肮脏的猫
A11: 24 | B11: 一只猴子的头骨
A12: 25 | B12: 血迹斑斑的本票
A13: 26 | B13: 母亲戴过的金首饰
... A37: 66 | B37: 家族流传下来的手稿

Sheet 辅助表
A1: 泛型 | B1: 资源下限 | C1: 资源上限 | D1: 天赋1 | E1: 天赋2 | F1: 天赋3 | G1: 主要属性 | H1: 主要技能 | I1: 装备
A2: =天赋表!A2 -> 学者 | B2: 4 | C2: 6 | D2: =天赋表!B2 -> 书虫 | E2: =天赋表!B3 -> 学富五车 | F2: =天赋表!B4 -> 知识是可靠的 | G2: 逻辑 | H2: 学习 | I2: 书本收藏或地图集，书写用具、液体或计算尺
A3: =天赋表!A5 -> 医生 | B3: 4 | C3: 6 | D3: =天赋表!B5 -> 军医 | E3: =天赋表!B6 -> 主任医师 | F3: =天赋表!B7 -> 应急医学 | G3: 逻辑 | H3: 医学 | I3: 装有医疗用品的医生背包、烈酒或好酒、瘦弱的马或强效毒药
A4: =天赋表!A8 -> 猎人 | B4: 2 | C4: 4 | D4: =天赋表!B8 -> 寻血犬 | E4: =天赋表!B9 -> 草药专家 | F4: =天赋表!B10 -> 神射手 | G4: 精准 | H4: 远程战斗 | I4: 来复枪、猎刀或猎犬、捕猎陷阱或捕猎装备
A5: =天赋表!A11 -> 神秘学家 | B5: 1 | C5: 4 | D5: =天赋表!B11 -> 魔术手法 | E5: =天赋表!B12 -> 灵媒 | F5: =天赋表!B13 -> 恐惧来袭 | G5: 精准 | H5: 隐秘行动 | I5: 水晶球、牡鹿角粉末或打火匣、匕首或锅
A6: =天赋表!A14 -> 军官 | B6: 3 | C6: 7 | D6: =天赋表!B14 -> 久经沙场 | E6: =天赋表!B15 -> 绅士 | F6: =天赋表!B16 -> 战术家 | G6: 精准 | H6: 远程战斗 | I6: 来复枪或手枪、指南针或刺刀、地图集或军刀
A7: =天赋表!A17 -> 牧师 | B7: 4 | C7: 5 | D7: =天赋表!B17 -> 赦免 | E7: =天赋表!B18 -> 祝福 | F7: =天赋表!B19 -> 忏悔者 | G7: 共情 | H7: 观察 | I7: 乐器或上好红酒、书写用具、圣水或旧圣经
A8: =天赋表!A20 -> 私家侦探 | B8: 2 | C8: 5 | D8: =天赋表!B20 -> 鹰眼 | E8: =天赋表!B21 -> 基础推演法 | F8: =天赋表!B22 -> 专注 | G8: 逻辑 | H8: 调查 | I8: 放大镜或撬锁器、左轮手枪、指虎或双筒望远镜
A9: =天赋表!A23 -> 仆人 | B9: 2 | C9: 4 | D9: =天赋表!B23 -> 忠诚 | E9: =天赋表!B24 -> 强硬如钉 | F9: =天赋表!B25 -> 坚韧 | G9: 体能 | H9: 蛮力 | I9: 左轮手枪、防风灯或化妆品、便携厨具或普通绷带
A10: =天赋表!A26 -> 流浪者 | B10: 1 | C10: 3 | D10: =天赋表!B26 -> 流浪者戏法 | E10: =天赋表!B27 -> 疑心 | F10: =天赋表!B28 -> 云游 | G10: 体能 | H10: 操控人心 | I10: 拐杖、小刀或撬棍、液体或宠物狗
A11: =天赋表!A29 -> 作家 | B11: 2 | C11: 5 | D11: =天赋表!B29 -> 自动书写 | E11: =天赋表!B30 -> 记者 | F11: =天赋表!B31 -> 墨客 | G11: 共情 | H11: 启迪 | I11: 书写用具和纸张、照相机或剧院望远镜、宠物狗或图书收藏
A12: 吸血鬼猎人 | B12: 1 | C12: 3 | D12: =天赋表!B32 -> 吸血者恨意 | E12: =天赋表!B33 -> 穿刺者 | F12: =天赋表!B34 -> 猎杀时刻 | G12: 精准 | H12: 近身战斗 | I12: 木桩、十字架项链、弩、剑。
A15: 年龄组 | B15: 属性点 | C15: 技能点 | D15: 属性辅助 | E15: 技能辅助
A16: 青年(17-25) | B16: 15 | C16: 10 | D16: =B16-SUM(角色卡!D20,角色卡!I20,角色卡!N20,角色卡!S20) -> 15 | E16: =C16-SUM(角色卡!C18,角色卡!D21:E23,角色卡!I21:J23,角色卡!N21:O23,角色卡!S21:T23) -> 10
A17: 中年(26-50) | B17: 14 | C17: 12 | D17: =B17-SUM(角色卡!D20,角色卡!I20,角色卡!N20,角色卡!S20) -> 14 | E17: =C17-SUM(角色卡!C18,角色卡!D21:E23,角色卡!I21:J23,角色卡!N21:O23,角色卡!S21:T23) -> 12
A18: 老年(51+) | B18: 13 | C18: 14 | D18: =B18-SUM(角色卡!D20,角色卡!I20,角色卡!N20,角色卡!S20) -> 13 | E18: =C18-SUM(角色卡!C18,角色卡!D21:E23,角色卡!I21:J23,角色卡!N21:O23,角色卡!S21:T23) -> 14
A20: 泛型天赋
A21: =A2 -> 学者 | B21: =D2 -> 书虫 | C21: =E2 -> 学富五车 | D21: =F2 -> 知识是可靠的
A22: =A3 -> 医生 | B22: =D3 -> 军医 | C22: =E3 -> 主任医师 | D22: =F3 -> 应急医学
A23: =A4 -> 猎人 | B23: =D4 -> 寻血犬 | C23: =E4 -> 草药专家 | D23: =F4 -> 神射手
A24: =A5 -> 神秘学家 | B24: =D5 -> 魔术手法 | C24: =E5 -> 灵媒 | D24: =F5 -> 恐惧来袭
A25: =A6 -> 军官 | B25: =D6 -> 久经沙场 | C25: =E6 -> 绅士 | D25: =F6 -> 战术家
A26: =A7 -> 牧师 | B26: =D7 -> 赦免 | C26: =E7 -> 祝福 | D26: =F7 -> 忏悔者
A27: =A8 -> 私家侦探 | B27: =D8 -> 鹰眼 | C27: =E8 -> 基础推演法 | D27: =F8 -> 专注
A28: =A9 -> 仆人 | B28: =D9 -> 忠诚 | C28: =E9 -> 强硬如钉 | D28: =F9 -> 坚韧
A29: =A10 -> 流浪者 | B29: =D10 -> 流浪者戏法 | C29: =E10 -> 疑心 | D29: =F10 -> 云游
A30: 作家 | B30: =D11 -> 自动书写 | C30: =E11 -> 记者 | D30: =F11 -> 墨客
A31: 吸血鬼猎人 | B31: =D12 -> 吸血者恨意 | C31: =E12 -> 穿刺者 | D31: =F12 -> 猎杀时刻

Sheet 更新记录
A2: Vaesen自动卡 by拂晓鵺啼
A4: 20220211 | B4: V1.0 | C4: 初版
A5: 20220226 | B5: v1.1 | C5: 解锁插入图片
A6: 22021210 | B6: v1.2 | C6: 修正T19的公式
A7: 20240508 | B7: v1.3 | C7: 修正医生的装备提示
A8: 20250725 | B8: v2.0 | C8: 增加扩展《喀尔巴阡》中的新泛型：吸血鬼猎人
